Watching for file changes with StatReloader
"GET / HTTP/1.1" 302 0
"GET /login/?next=/ HTTP/1.1" 200 2230
Not Found: /favicon.ico
"GET /favicon.ico HTTP/1.1" 404 3364
"POST /login/?next=/ HTTP/1.1" 200 2268
"GET /signup/ HTTP/1.1" 200 2666
"POST /signup/ HTTP/1.1" 302 0
"GET /login/ HTTP/1.1" 200 2230
- Broken pipe from ('127.0.0.1', 55788)
"POST /login/ HTTP/1.1" 302 0
"GET / HTTP/1.1" 200 2153
"GET /static/images/homepage.jpg HTTP/1.1" 304 0
"POST /home/homepage/ HTTP/1.1" 200 2647
"POST /home/homepage/ HTTP/1.1" 200 2647
"POST /home/homepage/ HTTP/1.1" 200 2647
Watching for file changes with StatReloader
"GET / HTTP/1.1" 200 2170
"GET /static/images/welcomepage.jpg HTTP/1.1" 200 234806
"GET / HTTP/1.1" 200 2192
"GET /static/images/welcomepage.jpg HTTP/1.1" 304 0
"GET / HTTP/1.1" 200 2157
"GET / HTTP/1.1" 200 2157
"GET / HTTP/1.1" 200 2190
"GET /static/images/welcomepage.jpg HTTP/1.1" 304 0
"GET / HTTP/1.1" 200 2214
"GET /static/images/welcomepage.jpg HTTP/1.1" 304 0
"GET / HTTP/1.1" 200 2223
"GET /static/images/welcomepage.jpg HTTP/1.1" 304 0
"GET / HTTP/1.1" 200 2230
"GET / HTTP/1.1" 200 2230
"GET / HTTP/1.1" 200 2229
"GET / HTTP/1.1" 200 2229
"GET / HTTP/1.1" 200 2229
"GET / HTTP/1.1" 200 2242
"GET / HTTP/1.1" 200 2242
"GET / HTTP/1.1" 200 2242
"GET / HTTP/1.1" 200 2119
"GET /static/images/welcomepage.jpg HTTP/1.1" 304 0
"GET / HTTP/1.1" 200 2150
"GET / HTTP/1.1" 200 2150
"GET / HTTP/1.1" 200 2150
"GET / HTTP/1.1" 200 2150
"GET / HTTP/1.1" 200 2157
"GET / HTTP/1.1" 200 2156
"GET / HTTP/1.1" 200 2156
"GET / HTTP/1.1" 200 2156
"GET / HTTP/1.1" 200 2167
"GET /static/images/welcomepage.jpg HTTP/1.1" 304 0
"GET / HTTP/1.1" 200 2168
"GET / HTTP/1.1" 200 2168
"GET / HTTP/1.1" 200 2167
"GET / HTTP/1.1" 200 2166
"GET / HTTP/1.1" 200 2166
"GET / HTTP/1.1" 200 2166
"GET / HTTP/1.1" 200 2168
"GET / HTTP/1.1" 200 2168
"GET / HTTP/1.1" 200 2168
"GET / HTTP/1.1" 200 2152
Not Found: /dashboard.html
"GET /dashboard.html HTTP/1.1" 404 3373
"GET / HTTP/1.1" 200 2154
Not Found: /dashboard.html
"GET /dashboard.html HTTP/1.1" 404 3373
"GET / HTTP/1.1" 200 2216
Not Found: /dashboard.html
"GET /dashboard.html HTTP/1.1" 404 3373
"GET / HTTP/1.1" 200 2216
Not Found: /dashboard.html
"GET /dashboard.html HTTP/1.1" 404 3373
"GET / HTTP/1.1" 200 2173
"GET /static/images/welcomepage.jpg HTTP/1.1" 304 0
"GET / HTTP/1.1" 200 2193
"GET / HTTP/1.1" 200 2193
"GET / HTTP/1.1" 200 2172
"GET / HTTP/1.1" 200 2172
"GET / HTTP/1.1" 200 2174
"GET / HTTP/1.1" 200 2174
"GET /static/images/welcomepage.jpg HTTP/1.1" 304 0
"GET / HTTP/1.1" 200 2174
"GET / HTTP/1.1" 200 2178
"GET / HTTP/1.1" 200 2048
"GET / HTTP/1.1" 200 2194
"GET /static/images/welcomepage.jpg HTTP/1.1" 304 0
"POST /home/homepage/ HTTP/1.1" 200 2805
"GET /static/images/homepage.jpg HTTP/1.1" 304 0
"GET /home/upload/ HTTP/1.1" 200 2617
"POST /home/upload/ HTTP/1.1" 302 0
"GET /home/homepage/ HTTP/1.1" 200 3465
"POST /home/homepage/ HTTP/1.1" 200 3465
"GET /home/homepage/ HTTP/1.1" 200 3465
"GET /home/upload/ HTTP/1.1" 200 2617
"GET / HTTP/1.1" 200 2194
"GET /static/images/welcomepage.jpg HTTP/1.1" 304 0
"POST /home/homepage/ HTTP/1.1" 200 3465
"POST /home/homepage/ HTTP/1.1" 200 3465
Watching for file changes with StatReloader
"GET / HTTP/1.1" 200 2194
"POST /home/homepage/ HTTP/1.1" 200 3465
"POST /home/homepage/ HTTP/1.1" 200 3465
"POST /home/homepage/ HTTP/1.1" 200 3465
Watching for file changes with StatReloader
Watching for file changes with StatReloader
"GET / HTTP/1.1" 200 2194
"GET /static/images/welcomepage.jpg HTTP/1.1" 200 234806
Not Found: /favicon.ico
"GET /favicon.ico HTTP/1.1" 404 3364
"GET /signout/ HTTP/1.1" 302 0
"GET /login/ HTTP/1.1" 200 2230
"GET /static/images/login_image.jpg HTTP/1.1" 200 67388
"POST /login/ HTTP/1.1" 302 0
"GET / HTTP/1.1" 200 2194
"POST /home/homepage/ HTTP/1.1" 200 3465
"GET /static/images/homepage.jpg HTTP/1.1" 200 57942
"POST /setting/settings/ HTTP/1.1" 200 4418
"GET /static/images/dashboard_image.jpg HTTP/1.1" 404 1938
"POST /setting/change_username/ HTTP/1.1" 200 2251
C:\Users\Ranjith\Desktop\Twitter\django_twitter\django_setting\forms.py changed, reloading.
Watching for file changes with StatReloader
Watching for file changes with StatReloader
C:\Users\Ranjith\Desktop\Twitter\django_twitter\django_accounts\models.py changed, reloading.
Watching for file changes with StatReloader
Watching for file changes with StatReloader
C:\Users\Ranjith\Desktop\Twitter\django_twitter\django_accounts\models.py changed, reloading.
Watching for file changes with StatReloader
C:\Users\Ranjith\Desktop\Twitter\django_twitter\django_accounts\models.py changed, reloading.
Watching for file changes with StatReloader
Watching for file changes with StatReloader
C:\Users\Ranjith\Desktop\Twitter\django_twitter\django_accounts\models.py changed, reloading.
Watching for file changes with StatReloader
Internal Server Error: /
Traceback (most recent call last):
  File "C:\Users\Ranjith\AppData\Local\Programs\Python\Python311\Lib\site-packages\django\db\backends\utils.py", line 89, in _execute
    return self.cursor.execute(sql, params)
           ^^^^^^^^^^^^^^^^^^^^^^^^^^^^^^^^
  File "C:\Users\Ranjith\AppData\Local\Programs\Python\Python311\Lib\site-packages\django\db\backends\sqlite3\base.py", line 328, in execute
    return super().execute(query, params)
           ^^^^^^^^^^^^^^^^^^^^^^^^^^^^^^
sqlite3.OperationalError: no such column: django_accounts_customuser.date_of_birth

The above exception was the direct cause of the following exception:

Traceback (most recent call last):
  File "C:\Users\Ranjith\AppData\Local\Programs\Python\Python311\Lib\site-packages\django\core\handlers\exception.py", line 55, in inner
    response = get_response(request)
               ^^^^^^^^^^^^^^^^^^^^^
  File "C:\Users\Ranjith\AppData\Local\Programs\Python\Python311\Lib\site-packages\django\core\handlers\base.py", line 197, in _get_response
    response = wrapped_callback(request, *callback_args, **callback_kwargs)
               ^^^^^^^^^^^^^^^^^^^^^^^^^^^^^^^^^^^^^^^^^^^^^^^^^^^^^^^^^^^^
  File "C:\Users\Ranjith\AppData\Local\Programs\Python\Python311\Lib\site-packages\django\contrib\auth\decorators.py", line 22, in _wrapper_view
    if test_func(request.user):
       ^^^^^^^^^^^^^^^^^^^^^^^
  File "C:\Users\Ranjith\AppData\Local\Programs\Python\Python311\Lib\site-packages\django\contrib\auth\decorators.py", line 51, in <lambda>
    lambda u: u.is_authenticated,
              ^^^^^^^^^^^^^^^^^^
  File "C:\Users\Ranjith\AppData\Local\Programs\Python\Python311\Lib\site-packages\django\utils\functional.py", line 266, in inner
    self._setup()
  File "C:\Users\Ranjith\AppData\Local\Programs\Python\Python311\Lib\site-packages\django\utils\functional.py", line 419, in _setup
    self._wrapped = self._setupfunc()
                    ^^^^^^^^^^^^^^^^^
  File "C:\Users\Ranjith\AppData\Local\Programs\Python\Python311\Lib\site-packages\django\contrib\auth\middleware.py", line 25, in <lambda>
    request.user = SimpleLazyObject(lambda: get_user(request))
                                            ^^^^^^^^^^^^^^^^^
  File "C:\Users\Ranjith\AppData\Local\Programs\Python\Python311\Lib\site-packages\django\contrib\auth\middleware.py", line 11, in get_user
    request._cached_user = auth.get_user(request)
                           ^^^^^^^^^^^^^^^^^^^^^^
  File "C:\Users\Ranjith\AppData\Local\Programs\Python\Python311\Lib\site-packages\django\contrib\auth\__init__.py", line 198, in get_user
    user = backend.get_user(user_id)
           ^^^^^^^^^^^^^^^^^^^^^^^^^
  File "C:\Users\Ranjith\AppData\Local\Programs\Python\Python311\Lib\site-packages\django\contrib\auth\backends.py", line 161, in get_user
    user = UserModel._default_manager.get(pk=user_id)
           ^^^^^^^^^^^^^^^^^^^^^^^^^^^^^^^^^^^^^^^^^^
  File "C:\Users\Ranjith\AppData\Local\Programs\Python\Python311\Lib\site-packages\django\db\models\manager.py", line 87, in manager_method
    return getattr(self.get_queryset(), name)(*args, **kwargs)
           ^^^^^^^^^^^^^^^^^^^^^^^^^^^^^^^^^^^^^^^^^^^^^^^^^^^
  File "C:\Users\Ranjith\AppData\Local\Programs\Python\Python311\Lib\site-packages\django\db\models\query.py", line 633, in get
    num = len(clone)
          ^^^^^^^^^^
  File "C:\Users\Ranjith\AppData\Local\Programs\Python\Python311\Lib\site-packages\django\db\models\query.py", line 380, in __len__
    self._fetch_all()
  File "C:\Users\Ranjith\AppData\Local\Programs\Python\Python311\Lib\site-packages\django\db\models\query.py", line 1881, in _fetch_all
    self._result_cache = list(self._iterable_class(self))
                         ^^^^^^^^^^^^^^^^^^^^^^^^^^^^^^^^
  File "C:\Users\Ranjith\AppData\Local\Programs\Python\Python311\Lib\site-packages\django\db\models\query.py", line 91, in __iter__
    results = compiler.execute_sql(
              ^^^^^^^^^^^^^^^^^^^^^
  File "C:\Users\Ranjith\AppData\Local\Programs\Python\Python311\Lib\site-packages\django\db\models\sql\compiler.py", line 1562, in execute_sql
    cursor.execute(sql, params)
  File "C:\Users\Ranjith\AppData\Local\Programs\Python\Python311\Lib\site-packages\django\db\backends\utils.py", line 102, in execute
    return super().execute(sql, params)
           ^^^^^^^^^^^^^^^^^^^^^^^^^^^^
  File "C:\Users\Ranjith\AppData\Local\Programs\Python\Python311\Lib\site-packages\django\db\backends\utils.py", line 67, in execute
    return self._execute_with_wrappers(
           ^^^^^^^^^^^^^^^^^^^^^^^^^^^^
  File "C:\Users\Ranjith\AppData\Local\Programs\Python\Python311\Lib\site-packages\django\db\backends\utils.py", line 80, in _execute_with_wrappers
    return executor(sql, params, many, context)
           ^^^^^^^^^^^^^^^^^^^^^^^^^^^^^^^^^^^^
  File "C:\Users\Ranjith\AppData\Local\Programs\Python\Python311\Lib\site-packages\django\db\backends\utils.py", line 84, in _execute
    with self.db.wrap_database_errors:
  File "C:\Users\Ranjith\AppData\Local\Programs\Python\Python311\Lib\site-packages\django\db\utils.py", line 91, in __exit__
    raise dj_exc_value.with_traceback(traceback) from exc_value
  File "C:\Users\Ranjith\AppData\Local\Programs\Python\Python311\Lib\site-packages\django\db\backends\utils.py", line 89, in _execute
    return self.cursor.execute(sql, params)
           ^^^^^^^^^^^^^^^^^^^^^^^^^^^^^^^^
  File "C:\Users\Ranjith\AppData\Local\Programs\Python\Python311\Lib\site-packages\django\db\backends\sqlite3\base.py", line 328, in execute
    return super().execute(query, params)
           ^^^^^^^^^^^^^^^^^^^^^^^^^^^^^^
django.db.utils.OperationalError: no such column: django_accounts_customuser.date_of_birth
"GET / HTTP/1.1" 500 171619
Internal Server Error: /
Traceback (most recent call last):
  File "C:\Users\Ranjith\AppData\Local\Programs\Python\Python311\Lib\site-packages\django\db\backends\utils.py", line 89, in _execute
    return self.cursor.execute(sql, params)
           ^^^^^^^^^^^^^^^^^^^^^^^^^^^^^^^^
  File "C:\Users\Ranjith\AppData\Local\Programs\Python\Python311\Lib\site-packages\django\db\backends\sqlite3\base.py", line 328, in execute
    return super().execute(query, params)
           ^^^^^^^^^^^^^^^^^^^^^^^^^^^^^^
sqlite3.OperationalError: no such column: django_accounts_customuser.date_of_birth

The above exception was the direct cause of the following exception:

Traceback (most recent call last):
  File "C:\Users\Ranjith\AppData\Local\Programs\Python\Python311\Lib\site-packages\django\core\handlers\exception.py", line 55, in inner
    response = get_response(request)
               ^^^^^^^^^^^^^^^^^^^^^
  File "C:\Users\Ranjith\AppData\Local\Programs\Python\Python311\Lib\site-packages\django\core\handlers\base.py", line 197, in _get_response
    response = wrapped_callback(request, *callback_args, **callback_kwargs)
               ^^^^^^^^^^^^^^^^^^^^^^^^^^^^^^^^^^^^^^^^^^^^^^^^^^^^^^^^^^^^
  File "C:\Users\Ranjith\AppData\Local\Programs\Python\Python311\Lib\site-packages\django\contrib\auth\decorators.py", line 22, in _wrapper_view
    if test_func(request.user):
       ^^^^^^^^^^^^^^^^^^^^^^^
  File "C:\Users\Ranjith\AppData\Local\Programs\Python\Python311\Lib\site-packages\django\contrib\auth\decorators.py", line 51, in <lambda>
    lambda u: u.is_authenticated,
              ^^^^^^^^^^^^^^^^^^
  File "C:\Users\Ranjith\AppData\Local\Programs\Python\Python311\Lib\site-packages\django\utils\functional.py", line 266, in inner
    self._setup()
  File "C:\Users\Ranjith\AppData\Local\Programs\Python\Python311\Lib\site-packages\django\utils\functional.py", line 419, in _setup
    self._wrapped = self._setupfunc()
                    ^^^^^^^^^^^^^^^^^
  File "C:\Users\Ranjith\AppData\Local\Programs\Python\Python311\Lib\site-packages\django\contrib\auth\middleware.py", line 25, in <lambda>
    request.user = SimpleLazyObject(lambda: get_user(request))
                                            ^^^^^^^^^^^^^^^^^
  File "C:\Users\Ranjith\AppData\Local\Programs\Python\Python311\Lib\site-packages\django\contrib\auth\middleware.py", line 11, in get_user
    request._cached_user = auth.get_user(request)
                           ^^^^^^^^^^^^^^^^^^^^^^
  File "C:\Users\Ranjith\AppData\Local\Programs\Python\Python311\Lib\site-packages\django\contrib\auth\__init__.py", line 198, in get_user
    user = backend.get_user(user_id)
           ^^^^^^^^^^^^^^^^^^^^^^^^^
  File "C:\Users\Ranjith\AppData\Local\Programs\Python\Python311\Lib\site-packages\django\contrib\auth\backends.py", line 161, in get_user
    user = UserModel._default_manager.get(pk=user_id)
           ^^^^^^^^^^^^^^^^^^^^^^^^^^^^^^^^^^^^^^^^^^
  File "C:\Users\Ranjith\AppData\Local\Programs\Python\Python311\Lib\site-packages\django\db\models\manager.py", line 87, in manager_method
    return getattr(self.get_queryset(), name)(*args, **kwargs)
           ^^^^^^^^^^^^^^^^^^^^^^^^^^^^^^^^^^^^^^^^^^^^^^^^^^^
  File "C:\Users\Ranjith\AppData\Local\Programs\Python\Python311\Lib\site-packages\django\db\models\query.py", line 633, in get
    num = len(clone)
          ^^^^^^^^^^
  File "C:\Users\Ranjith\AppData\Local\Programs\Python\Python311\Lib\site-packages\django\db\models\query.py", line 380, in __len__
    self._fetch_all()
  File "C:\Users\Ranjith\AppData\Local\Programs\Python\Python311\Lib\site-packages\django\db\models\query.py", line 1881, in _fetch_all
    self._result_cache = list(self._iterable_class(self))
                         ^^^^^^^^^^^^^^^^^^^^^^^^^^^^^^^^
  File "C:\Users\Ranjith\AppData\Local\Programs\Python\Python311\Lib\site-packages\django\db\models\query.py", line 91, in __iter__
    results = compiler.execute_sql(
              ^^^^^^^^^^^^^^^^^^^^^
  File "C:\Users\Ranjith\AppData\Local\Programs\Python\Python311\Lib\site-packages\django\db\models\sql\compiler.py", line 1562, in execute_sql
    cursor.execute(sql, params)
  File "C:\Users\Ranjith\AppData\Local\Programs\Python\Python311\Lib\site-packages\django\db\backends\utils.py", line 102, in execute
    return super().execute(sql, params)
           ^^^^^^^^^^^^^^^^^^^^^^^^^^^^
  File "C:\Users\Ranjith\AppData\Local\Programs\Python\Python311\Lib\site-packages\django\db\backends\utils.py", line 67, in execute
    return self._execute_with_wrappers(
           ^^^^^^^^^^^^^^^^^^^^^^^^^^^^
  File "C:\Users\Ranjith\AppData\Local\Programs\Python\Python311\Lib\site-packages\django\db\backends\utils.py", line 80, in _execute_with_wrappers
    return executor(sql, params, many, context)
           ^^^^^^^^^^^^^^^^^^^^^^^^^^^^^^^^^^^^
  File "C:\Users\Ranjith\AppData\Local\Programs\Python\Python311\Lib\site-packages\django\db\backends\utils.py", line 84, in _execute
    with self.db.wrap_database_errors:
  File "C:\Users\Ranjith\AppData\Local\Programs\Python\Python311\Lib\site-packages\django\db\utils.py", line 91, in __exit__
    raise dj_exc_value.with_traceback(traceback) from exc_value
  File "C:\Users\Ranjith\AppData\Local\Programs\Python\Python311\Lib\site-packages\django\db\backends\utils.py", line 89, in _execute
    return self.cursor.execute(sql, params)
           ^^^^^^^^^^^^^^^^^^^^^^^^^^^^^^^^
  File "C:\Users\Ranjith\AppData\Local\Programs\Python\Python311\Lib\site-packages\django\db\backends\sqlite3\base.py", line 328, in execute
    return super().execute(query, params)
           ^^^^^^^^^^^^^^^^^^^^^^^^^^^^^^
django.db.utils.OperationalError: no such column: django_accounts_customuser.date_of_birth
"GET / HTTP/1.1" 500 171619
C:\Users\Ranjith\Desktop\Twitter\django_twitter\django_accounts\models.py changed, reloading.
Watching for file changes with StatReloader
C:\Users\Ranjith\Desktop\Twitter\django_twitter\django_accounts\models.py changed, reloading.
Watching for file changes with StatReloader
Internal Server Error: /
Traceback (most recent call last):
  File "C:\Users\Ranjith\AppData\Local\Programs\Python\Python311\Lib\site-packages\django\db\backends\utils.py", line 89, in _execute
    return self.cursor.execute(sql, params)
           ^^^^^^^^^^^^^^^^^^^^^^^^^^^^^^^^
  File "C:\Users\Ranjith\AppData\Local\Programs\Python\Python311\Lib\site-packages\django\db\backends\sqlite3\base.py", line 328, in execute
    return super().execute(query, params)
           ^^^^^^^^^^^^^^^^^^^^^^^^^^^^^^
sqlite3.OperationalError: no such column: django_accounts_customuser.date_of_birth

The above exception was the direct cause of the following exception:

Traceback (most recent call last):
  File "C:\Users\Ranjith\AppData\Local\Programs\Python\Python311\Lib\site-packages\django\core\handlers\exception.py", line 55, in inner
    response = get_response(request)
               ^^^^^^^^^^^^^^^^^^^^^
  File "C:\Users\Ranjith\AppData\Local\Programs\Python\Python311\Lib\site-packages\django\core\handlers\base.py", line 197, in _get_response
    response = wrapped_callback(request, *callback_args, **callback_kwargs)
               ^^^^^^^^^^^^^^^^^^^^^^^^^^^^^^^^^^^^^^^^^^^^^^^^^^^^^^^^^^^^
  File "C:\Users\Ranjith\AppData\Local\Programs\Python\Python311\Lib\site-packages\django\contrib\auth\decorators.py", line 22, in _wrapper_view
    if test_func(request.user):
       ^^^^^^^^^^^^^^^^^^^^^^^
  File "C:\Users\Ranjith\AppData\Local\Programs\Python\Python311\Lib\site-packages\django\contrib\auth\decorators.py", line 51, in <lambda>
    lambda u: u.is_authenticated,
              ^^^^^^^^^^^^^^^^^^
  File "C:\Users\Ranjith\AppData\Local\Programs\Python\Python311\Lib\site-packages\django\utils\functional.py", line 266, in inner
    self._setup()
  File "C:\Users\Ranjith\AppData\Local\Programs\Python\Python311\Lib\site-packages\django\utils\functional.py", line 419, in _setup
    self._wrapped = self._setupfunc()
                    ^^^^^^^^^^^^^^^^^
  File "C:\Users\Ranjith\AppData\Local\Programs\Python\Python311\Lib\site-packages\django\contrib\auth\middleware.py", line 25, in <lambda>
    request.user = SimpleLazyObject(lambda: get_user(request))
                                            ^^^^^^^^^^^^^^^^^
  File "C:\Users\Ranjith\AppData\Local\Programs\Python\Python311\Lib\site-packages\django\contrib\auth\middleware.py", line 11, in get_user
    request._cached_user = auth.get_user(request)
                           ^^^^^^^^^^^^^^^^^^^^^^
  File "C:\Users\Ranjith\AppData\Local\Programs\Python\Python311\Lib\site-packages\django\contrib\auth\__init__.py", line 198, in get_user
    user = backend.get_user(user_id)
           ^^^^^^^^^^^^^^^^^^^^^^^^^
  File "C:\Users\Ranjith\AppData\Local\Programs\Python\Python311\Lib\site-packages\django\contrib\auth\backends.py", line 161, in get_user
    user = UserModel._default_manager.get(pk=user_id)
           ^^^^^^^^^^^^^^^^^^^^^^^^^^^^^^^^^^^^^^^^^^
  File "C:\Users\Ranjith\AppData\Local\Programs\Python\Python311\Lib\site-packages\django\db\models\manager.py", line 87, in manager_method
    return getattr(self.get_queryset(), name)(*args, **kwargs)
           ^^^^^^^^^^^^^^^^^^^^^^^^^^^^^^^^^^^^^^^^^^^^^^^^^^^
  File "C:\Users\Ranjith\AppData\Local\Programs\Python\Python311\Lib\site-packages\django\db\models\query.py", line 633, in get
    num = len(clone)
          ^^^^^^^^^^
  File "C:\Users\Ranjith\AppData\Local\Programs\Python\Python311\Lib\site-packages\django\db\models\query.py", line 380, in __len__
    self._fetch_all()
  File "C:\Users\Ranjith\AppData\Local\Programs\Python\Python311\Lib\site-packages\django\db\models\query.py", line 1881, in _fetch_all
    self._result_cache = list(self._iterable_class(self))
                         ^^^^^^^^^^^^^^^^^^^^^^^^^^^^^^^^
  File "C:\Users\Ranjith\AppData\Local\Programs\Python\Python311\Lib\site-packages\django\db\models\query.py", line 91, in __iter__
    results = compiler.execute_sql(
              ^^^^^^^^^^^^^^^^^^^^^
  File "C:\Users\Ranjith\AppData\Local\Programs\Python\Python311\Lib\site-packages\django\db\models\sql\compiler.py", line 1562, in execute_sql
    cursor.execute(sql, params)
  File "C:\Users\Ranjith\AppData\Local\Programs\Python\Python311\Lib\site-packages\django\db\backends\utils.py", line 102, in execute
    return super().execute(sql, params)
           ^^^^^^^^^^^^^^^^^^^^^^^^^^^^
  File "C:\Users\Ranjith\AppData\Local\Programs\Python\Python311\Lib\site-packages\django\db\backends\utils.py", line 67, in execute
    return self._execute_with_wrappers(
           ^^^^^^^^^^^^^^^^^^^^^^^^^^^^
  File "C:\Users\Ranjith\AppData\Local\Programs\Python\Python311\Lib\site-packages\django\db\backends\utils.py", line 80, in _execute_with_wrappers
    return executor(sql, params, many, context)
           ^^^^^^^^^^^^^^^^^^^^^^^^^^^^^^^^^^^^
  File "C:\Users\Ranjith\AppData\Local\Programs\Python\Python311\Lib\site-packages\django\db\backends\utils.py", line 84, in _execute
    with self.db.wrap_database_errors:
  File "C:\Users\Ranjith\AppData\Local\Programs\Python\Python311\Lib\site-packages\django\db\utils.py", line 91, in __exit__
    raise dj_exc_value.with_traceback(traceback) from exc_value
  File "C:\Users\Ranjith\AppData\Local\Programs\Python\Python311\Lib\site-packages\django\db\backends\utils.py", line 89, in _execute
    return self.cursor.execute(sql, params)
           ^^^^^^^^^^^^^^^^^^^^^^^^^^^^^^^^
  File "C:\Users\Ranjith\AppData\Local\Programs\Python\Python311\Lib\site-packages\django\db\backends\sqlite3\base.py", line 328, in execute
    return super().execute(query, params)
           ^^^^^^^^^^^^^^^^^^^^^^^^^^^^^^
django.db.utils.OperationalError: no such column: django_accounts_customuser.date_of_birth
"GET / HTTP/1.1" 500 171619
Watching for file changes with StatReloader
"GET / HTTP/1.1" 200 2194
"GET /static/images/welcomepage.jpg HTTP/1.1" 304 0
Not Found: /favicon.ico
"GET /favicon.ico HTTP/1.1" 404 3364
"GET /signout/ HTTP/1.1" 302 0
"GET /login/ HTTP/1.1" 200 2230
"GET /signup/ HTTP/1.1" 200 2742
"GET /static/images/signup_image.jpg HTTP/1.1" 200 77638
"POST /login/ HTTP/1.1" 302 0
"GET / HTTP/1.1" 200 2194
"POST /home/homepage/ HTTP/1.1" 200 3465
"GET /static/images/homepage.jpg HTTP/1.1" 304 0
"POST /setting/settings/ HTTP/1.1" 200 4418
"GET /static/images/dashboard_image.jpg HTTP/1.1" 404 1938
Watching for file changes with StatReloader
Internal Server Error: /
Traceback (most recent call last):
  File "C:\Users\Ranjith\AppData\Local\Programs\Python\Python311\Lib\site-packages\django\db\backends\utils.py", line 89, in _execute
    return self.cursor.execute(sql, params)
           ^^^^^^^^^^^^^^^^^^^^^^^^^^^^^^^^
  File "C:\Users\Ranjith\AppData\Local\Programs\Python\Python311\Lib\site-packages\django\db\backends\sqlite3\base.py", line 328, in execute
    return super().execute(query, params)
           ^^^^^^^^^^^^^^^^^^^^^^^^^^^^^^
sqlite3.OperationalError: no such column: django_accounts_customuser.date_of_birth

The above exception was the direct cause of the following exception:

Traceback (most recent call last):
  File "C:\Users\Ranjith\AppData\Local\Programs\Python\Python311\Lib\site-packages\django\core\handlers\exception.py", line 55, in inner
    response = get_response(request)
               ^^^^^^^^^^^^^^^^^^^^^
  File "C:\Users\Ranjith\AppData\Local\Programs\Python\Python311\Lib\site-packages\django\core\handlers\base.py", line 197, in _get_response
    response = wrapped_callback(request, *callback_args, **callback_kwargs)
               ^^^^^^^^^^^^^^^^^^^^^^^^^^^^^^^^^^^^^^^^^^^^^^^^^^^^^^^^^^^^
  File "C:\Users\Ranjith\AppData\Local\Programs\Python\Python311\Lib\site-packages\django\contrib\auth\decorators.py", line 22, in _wrapper_view
    if test_func(request.user):
       ^^^^^^^^^^^^^^^^^^^^^^^
  File "C:\Users\Ranjith\AppData\Local\Programs\Python\Python311\Lib\site-packages\django\contrib\auth\decorators.py", line 51, in <lambda>
    lambda u: u.is_authenticated,
              ^^^^^^^^^^^^^^^^^^
  File "C:\Users\Ranjith\AppData\Local\Programs\Python\Python311\Lib\site-packages\django\utils\functional.py", line 266, in inner
    self._setup()
  File "C:\Users\Ranjith\AppData\Local\Programs\Python\Python311\Lib\site-packages\django\utils\functional.py", line 419, in _setup
    self._wrapped = self._setupfunc()
                    ^^^^^^^^^^^^^^^^^
  File "C:\Users\Ranjith\AppData\Local\Programs\Python\Python311\Lib\site-packages\django\contrib\auth\middleware.py", line 25, in <lambda>
    request.user = SimpleLazyObject(lambda: get_user(request))
                                            ^^^^^^^^^^^^^^^^^
  File "C:\Users\Ranjith\AppData\Local\Programs\Python\Python311\Lib\site-packages\django\contrib\auth\middleware.py", line 11, in get_user
    request._cached_user = auth.get_user(request)
                           ^^^^^^^^^^^^^^^^^^^^^^
  File "C:\Users\Ranjith\AppData\Local\Programs\Python\Python311\Lib\site-packages\django\contrib\auth\__init__.py", line 198, in get_user
    user = backend.get_user(user_id)
           ^^^^^^^^^^^^^^^^^^^^^^^^^
  File "C:\Users\Ranjith\AppData\Local\Programs\Python\Python311\Lib\site-packages\django\contrib\auth\backends.py", line 161, in get_user
    user = UserModel._default_manager.get(pk=user_id)
           ^^^^^^^^^^^^^^^^^^^^^^^^^^^^^^^^^^^^^^^^^^
  File "C:\Users\Ranjith\AppData\Local\Programs\Python\Python311\Lib\site-packages\django\db\models\manager.py", line 87, in manager_method
    return getattr(self.get_queryset(), name)(*args, **kwargs)
           ^^^^^^^^^^^^^^^^^^^^^^^^^^^^^^^^^^^^^^^^^^^^^^^^^^^
  File "C:\Users\Ranjith\AppData\Local\Programs\Python\Python311\Lib\site-packages\django\db\models\query.py", line 633, in get
    num = len(clone)
          ^^^^^^^^^^
  File "C:\Users\Ranjith\AppData\Local\Programs\Python\Python311\Lib\site-packages\django\db\models\query.py", line 380, in __len__
    self._fetch_all()
  File "C:\Users\Ranjith\AppData\Local\Programs\Python\Python311\Lib\site-packages\django\db\models\query.py", line 1881, in _fetch_all
    self._result_cache = list(self._iterable_class(self))
                         ^^^^^^^^^^^^^^^^^^^^^^^^^^^^^^^^
  File "C:\Users\Ranjith\AppData\Local\Programs\Python\Python311\Lib\site-packages\django\db\models\query.py", line 91, in __iter__
    results = compiler.execute_sql(
              ^^^^^^^^^^^^^^^^^^^^^
  File "C:\Users\Ranjith\AppData\Local\Programs\Python\Python311\Lib\site-packages\django\db\models\sql\compiler.py", line 1562, in execute_sql
    cursor.execute(sql, params)
  File "C:\Users\Ranjith\AppData\Local\Programs\Python\Python311\Lib\site-packages\django\db\backends\utils.py", line 102, in execute
    return super().execute(sql, params)
           ^^^^^^^^^^^^^^^^^^^^^^^^^^^^
  File "C:\Users\Ranjith\AppData\Local\Programs\Python\Python311\Lib\site-packages\django\db\backends\utils.py", line 67, in execute
    return self._execute_with_wrappers(
           ^^^^^^^^^^^^^^^^^^^^^^^^^^^^
  File "C:\Users\Ranjith\AppData\Local\Programs\Python\Python311\Lib\site-packages\django\db\backends\utils.py", line 80, in _execute_with_wrappers
    return executor(sql, params, many, context)
           ^^^^^^^^^^^^^^^^^^^^^^^^^^^^^^^^^^^^
  File "C:\Users\Ranjith\AppData\Local\Programs\Python\Python311\Lib\site-packages\django\db\backends\utils.py", line 84, in _execute
    with self.db.wrap_database_errors:
  File "C:\Users\Ranjith\AppData\Local\Programs\Python\Python311\Lib\site-packages\django\db\utils.py", line 91, in __exit__
    raise dj_exc_value.with_traceback(traceback) from exc_value
  File "C:\Users\Ranjith\AppData\Local\Programs\Python\Python311\Lib\site-packages\django\db\backends\utils.py", line 89, in _execute
    return self.cursor.execute(sql, params)
           ^^^^^^^^^^^^^^^^^^^^^^^^^^^^^^^^
  File "C:\Users\Ranjith\AppData\Local\Programs\Python\Python311\Lib\site-packages\django\db\backends\sqlite3\base.py", line 328, in execute
    return super().execute(query, params)
           ^^^^^^^^^^^^^^^^^^^^^^^^^^^^^^
django.db.utils.OperationalError: no such column: django_accounts_customuser.date_of_birth
"GET / HTTP/1.1" 500 170877
Not Found: /favicon.ico
"GET /favicon.ico HTTP/1.1" 404 3364
C:\Users\Ranjith\Desktop\Twitter\django_twitter\django_accounts\models.py changed, reloading.
Watching for file changes with StatReloader
Internal Server Error: /
Traceback (most recent call last):
  File "C:\Users\Ranjith\AppData\Local\Programs\Python\Python311\Lib\site-packages\django\db\backends\utils.py", line 89, in _execute
    return self.cursor.execute(sql, params)
           ^^^^^^^^^^^^^^^^^^^^^^^^^^^^^^^^
  File "C:\Users\Ranjith\AppData\Local\Programs\Python\Python311\Lib\site-packages\django\db\backends\sqlite3\base.py", line 328, in execute
    return super().execute(query, params)
           ^^^^^^^^^^^^^^^^^^^^^^^^^^^^^^
sqlite3.OperationalError: no such column: django_accounts_customuser.date_of_birth

The above exception was the direct cause of the following exception:

Traceback (most recent call last):
  File "C:\Users\Ranjith\AppData\Local\Programs\Python\Python311\Lib\site-packages\django\core\handlers\exception.py", line 55, in inner
    response = get_response(request)
               ^^^^^^^^^^^^^^^^^^^^^
  File "C:\Users\Ranjith\AppData\Local\Programs\Python\Python311\Lib\site-packages\django\core\handlers\base.py", line 197, in _get_response
    response = wrapped_callback(request, *callback_args, **callback_kwargs)
               ^^^^^^^^^^^^^^^^^^^^^^^^^^^^^^^^^^^^^^^^^^^^^^^^^^^^^^^^^^^^
  File "C:\Users\Ranjith\AppData\Local\Programs\Python\Python311\Lib\site-packages\django\contrib\auth\decorators.py", line 22, in _wrapper_view
    if test_func(request.user):
       ^^^^^^^^^^^^^^^^^^^^^^^
  File "C:\Users\Ranjith\AppData\Local\Programs\Python\Python311\Lib\site-packages\django\contrib\auth\decorators.py", line 51, in <lambda>
    lambda u: u.is_authenticated,
              ^^^^^^^^^^^^^^^^^^
  File "C:\Users\Ranjith\AppData\Local\Programs\Python\Python311\Lib\site-packages\django\utils\functional.py", line 266, in inner
    self._setup()
  File "C:\Users\Ranjith\AppData\Local\Programs\Python\Python311\Lib\site-packages\django\utils\functional.py", line 419, in _setup
    self._wrapped = self._setupfunc()
                    ^^^^^^^^^^^^^^^^^
  File "C:\Users\Ranjith\AppData\Local\Programs\Python\Python311\Lib\site-packages\django\contrib\auth\middleware.py", line 25, in <lambda>
    request.user = SimpleLazyObject(lambda: get_user(request))
                                            ^^^^^^^^^^^^^^^^^
  File "C:\Users\Ranjith\AppData\Local\Programs\Python\Python311\Lib\site-packages\django\contrib\auth\middleware.py", line 11, in get_user
    request._cached_user = auth.get_user(request)
                           ^^^^^^^^^^^^^^^^^^^^^^
  File "C:\Users\Ranjith\AppData\Local\Programs\Python\Python311\Lib\site-packages\django\contrib\auth\__init__.py", line 198, in get_user
    user = backend.get_user(user_id)
           ^^^^^^^^^^^^^^^^^^^^^^^^^
  File "C:\Users\Ranjith\AppData\Local\Programs\Python\Python311\Lib\site-packages\django\contrib\auth\backends.py", line 161, in get_user
    user = UserModel._default_manager.get(pk=user_id)
           ^^^^^^^^^^^^^^^^^^^^^^^^^^^^^^^^^^^^^^^^^^
  File "C:\Users\Ranjith\AppData\Local\Programs\Python\Python311\Lib\site-packages\django\db\models\manager.py", line 87, in manager_method
    return getattr(self.get_queryset(), name)(*args, **kwargs)
           ^^^^^^^^^^^^^^^^^^^^^^^^^^^^^^^^^^^^^^^^^^^^^^^^^^^
  File "C:\Users\Ranjith\AppData\Local\Programs\Python\Python311\Lib\site-packages\django\db\models\query.py", line 633, in get
    num = len(clone)
          ^^^^^^^^^^
  File "C:\Users\Ranjith\AppData\Local\Programs\Python\Python311\Lib\site-packages\django\db\models\query.py", line 380, in __len__
    self._fetch_all()
  File "C:\Users\Ranjith\AppData\Local\Programs\Python\Python311\Lib\site-packages\django\db\models\query.py", line 1881, in _fetch_all
    self._result_cache = list(self._iterable_class(self))
                         ^^^^^^^^^^^^^^^^^^^^^^^^^^^^^^^^
  File "C:\Users\Ranjith\AppData\Local\Programs\Python\Python311\Lib\site-packages\django\db\models\query.py", line 91, in __iter__
    results = compiler.execute_sql(
              ^^^^^^^^^^^^^^^^^^^^^
  File "C:\Users\Ranjith\AppData\Local\Programs\Python\Python311\Lib\site-packages\django\db\models\sql\compiler.py", line 1562, in execute_sql
    cursor.execute(sql, params)
  File "C:\Users\Ranjith\AppData\Local\Programs\Python\Python311\Lib\site-packages\django\db\backends\utils.py", line 102, in execute
    return super().execute(sql, params)
           ^^^^^^^^^^^^^^^^^^^^^^^^^^^^
  File "C:\Users\Ranjith\AppData\Local\Programs\Python\Python311\Lib\site-packages\django\db\backends\utils.py", line 67, in execute
    return self._execute_with_wrappers(
           ^^^^^^^^^^^^^^^^^^^^^^^^^^^^
  File "C:\Users\Ranjith\AppData\Local\Programs\Python\Python311\Lib\site-packages\django\db\backends\utils.py", line 80, in _execute_with_wrappers
    return executor(sql, params, many, context)
           ^^^^^^^^^^^^^^^^^^^^^^^^^^^^^^^^^^^^
  File "C:\Users\Ranjith\AppData\Local\Programs\Python\Python311\Lib\site-packages\django\db\backends\utils.py", line 84, in _execute
    with self.db.wrap_database_errors:
  File "C:\Users\Ranjith\AppData\Local\Programs\Python\Python311\Lib\site-packages\django\db\utils.py", line 91, in __exit__
    raise dj_exc_value.with_traceback(traceback) from exc_value
  File "C:\Users\Ranjith\AppData\Local\Programs\Python\Python311\Lib\site-packages\django\db\backends\utils.py", line 89, in _execute
    return self.cursor.execute(sql, params)
           ^^^^^^^^^^^^^^^^^^^^^^^^^^^^^^^^
  File "C:\Users\Ranjith\AppData\Local\Programs\Python\Python311\Lib\site-packages\django\db\backends\sqlite3\base.py", line 328, in execute
    return super().execute(query, params)
           ^^^^^^^^^^^^^^^^^^^^^^^^^^^^^^
django.db.utils.OperationalError: no such column: django_accounts_customuser.date_of_birth
"GET / HTTP/1.1" 500 170877
C:\Users\Ranjith\Desktop\Twitter\django_twitter\django_accounts\views.py changed, reloading.
Watching for file changes with StatReloader
Internal Server Error: /
Traceback (most recent call last):
  File "C:\Users\Ranjith\AppData\Local\Programs\Python\Python311\Lib\site-packages\django\db\backends\utils.py", line 89, in _execute
    return self.cursor.execute(sql, params)
           ^^^^^^^^^^^^^^^^^^^^^^^^^^^^^^^^
  File "C:\Users\Ranjith\AppData\Local\Programs\Python\Python311\Lib\site-packages\django\db\backends\sqlite3\base.py", line 328, in execute
    return super().execute(query, params)
           ^^^^^^^^^^^^^^^^^^^^^^^^^^^^^^
sqlite3.OperationalError: no such column: django_accounts_customuser.date_of_birth

The above exception was the direct cause of the following exception:

Traceback (most recent call last):
  File "C:\Users\Ranjith\AppData\Local\Programs\Python\Python311\Lib\site-packages\django\core\handlers\exception.py", line 55, in inner
    response = get_response(request)
               ^^^^^^^^^^^^^^^^^^^^^
  File "C:\Users\Ranjith\AppData\Local\Programs\Python\Python311\Lib\site-packages\django\core\handlers\base.py", line 197, in _get_response
    response = wrapped_callback(request, *callback_args, **callback_kwargs)
               ^^^^^^^^^^^^^^^^^^^^^^^^^^^^^^^^^^^^^^^^^^^^^^^^^^^^^^^^^^^^
  File "C:\Users\Ranjith\AppData\Local\Programs\Python\Python311\Lib\site-packages\django\contrib\auth\decorators.py", line 22, in _wrapper_view
    if test_func(request.user):
       ^^^^^^^^^^^^^^^^^^^^^^^
  File "C:\Users\Ranjith\AppData\Local\Programs\Python\Python311\Lib\site-packages\django\contrib\auth\decorators.py", line 51, in <lambda>
    lambda u: u.is_authenticated,
              ^^^^^^^^^^^^^^^^^^
  File "C:\Users\Ranjith\AppData\Local\Programs\Python\Python311\Lib\site-packages\django\utils\functional.py", line 266, in inner
    self._setup()
  File "C:\Users\Ranjith\AppData\Local\Programs\Python\Python311\Lib\site-packages\django\utils\functional.py", line 419, in _setup
    self._wrapped = self._setupfunc()
                    ^^^^^^^^^^^^^^^^^
  File "C:\Users\Ranjith\AppData\Local\Programs\Python\Python311\Lib\site-packages\django\contrib\auth\middleware.py", line 25, in <lambda>
    request.user = SimpleLazyObject(lambda: get_user(request))
                                            ^^^^^^^^^^^^^^^^^
  File "C:\Users\Ranjith\AppData\Local\Programs\Python\Python311\Lib\site-packages\django\contrib\auth\middleware.py", line 11, in get_user
    request._cached_user = auth.get_user(request)
                           ^^^^^^^^^^^^^^^^^^^^^^
  File "C:\Users\Ranjith\AppData\Local\Programs\Python\Python311\Lib\site-packages\django\contrib\auth\__init__.py", line 198, in get_user
    user = backend.get_user(user_id)
           ^^^^^^^^^^^^^^^^^^^^^^^^^
  File "C:\Users\Ranjith\AppData\Local\Programs\Python\Python311\Lib\site-packages\django\contrib\auth\backends.py", line 161, in get_user
    user = UserModel._default_manager.get(pk=user_id)
           ^^^^^^^^^^^^^^^^^^^^^^^^^^^^^^^^^^^^^^^^^^
  File "C:\Users\Ranjith\AppData\Local\Programs\Python\Python311\Lib\site-packages\django\db\models\manager.py", line 87, in manager_method
    return getattr(self.get_queryset(), name)(*args, **kwargs)
           ^^^^^^^^^^^^^^^^^^^^^^^^^^^^^^^^^^^^^^^^^^^^^^^^^^^
  File "C:\Users\Ranjith\AppData\Local\Programs\Python\Python311\Lib\site-packages\django\db\models\query.py", line 633, in get
    num = len(clone)
          ^^^^^^^^^^
  File "C:\Users\Ranjith\AppData\Local\Programs\Python\Python311\Lib\site-packages\django\db\models\query.py", line 380, in __len__
    self._fetch_all()
  File "C:\Users\Ranjith\AppData\Local\Programs\Python\Python311\Lib\site-packages\django\db\models\query.py", line 1881, in _fetch_all
    self._result_cache = list(self._iterable_class(self))
                         ^^^^^^^^^^^^^^^^^^^^^^^^^^^^^^^^
  File "C:\Users\Ranjith\AppData\Local\Programs\Python\Python311\Lib\site-packages\django\db\models\query.py", line 91, in __iter__
    results = compiler.execute_sql(
              ^^^^^^^^^^^^^^^^^^^^^
  File "C:\Users\Ranjith\AppData\Local\Programs\Python\Python311\Lib\site-packages\django\db\models\sql\compiler.py", line 1562, in execute_sql
    cursor.execute(sql, params)
  File "C:\Users\Ranjith\AppData\Local\Programs\Python\Python311\Lib\site-packages\django\db\backends\utils.py", line 102, in execute
    return super().execute(sql, params)
           ^^^^^^^^^^^^^^^^^^^^^^^^^^^^
  File "C:\Users\Ranjith\AppData\Local\Programs\Python\Python311\Lib\site-packages\django\db\backends\utils.py", line 67, in execute
    return self._execute_with_wrappers(
           ^^^^^^^^^^^^^^^^^^^^^^^^^^^^
  File "C:\Users\Ranjith\AppData\Local\Programs\Python\Python311\Lib\site-packages\django\db\backends\utils.py", line 80, in _execute_with_wrappers
    return executor(sql, params, many, context)
           ^^^^^^^^^^^^^^^^^^^^^^^^^^^^^^^^^^^^
  File "C:\Users\Ranjith\AppData\Local\Programs\Python\Python311\Lib\site-packages\django\db\backends\utils.py", line 84, in _execute
    with self.db.wrap_database_errors:
  File "C:\Users\Ranjith\AppData\Local\Programs\Python\Python311\Lib\site-packages\django\db\utils.py", line 91, in __exit__
    raise dj_exc_value.with_traceback(traceback) from exc_value
  File "C:\Users\Ranjith\AppData\Local\Programs\Python\Python311\Lib\site-packages\django\db\backends\utils.py", line 89, in _execute
    return self.cursor.execute(sql, params)
           ^^^^^^^^^^^^^^^^^^^^^^^^^^^^^^^^
  File "C:\Users\Ranjith\AppData\Local\Programs\Python\Python311\Lib\site-packages\django\db\backends\sqlite3\base.py", line 328, in execute
    return super().execute(query, params)
           ^^^^^^^^^^^^^^^^^^^^^^^^^^^^^^
django.db.utils.OperationalError: no such column: django_accounts_customuser.date_of_birth
"GET / HTTP/1.1" 500 170877
C:\Users\Ranjith\Desktop\Twitter\django_twitter\django_accounts\models.py changed, reloading.
Watching for file changes with StatReloader
C:\Users\Ranjith\Desktop\Twitter\django_twitter\django_accounts\views.py changed, reloading.
Watching for file changes with StatReloader
C:\Users\Ranjith\Desktop\Twitter\django_twitter\django_accounts\urls.py changed, reloading.
Watching for file changes with StatReloader
Internal Server Error: /
Traceback (most recent call last):
  File "C:\Users\Ranjith\AppData\Local\Programs\Python\Python311\Lib\site-packages\django\db\backends\utils.py", line 89, in _execute
    return self.cursor.execute(sql, params)
           ^^^^^^^^^^^^^^^^^^^^^^^^^^^^^^^^
  File "C:\Users\Ranjith\AppData\Local\Programs\Python\Python311\Lib\site-packages\django\db\backends\sqlite3\base.py", line 328, in execute
    return super().execute(query, params)
           ^^^^^^^^^^^^^^^^^^^^^^^^^^^^^^
sqlite3.OperationalError: no such column: django_accounts_customuser.date_of_birth

The above exception was the direct cause of the following exception:

Traceback (most recent call last):
  File "C:\Users\Ranjith\AppData\Local\Programs\Python\Python311\Lib\site-packages\django\core\handlers\exception.py", line 55, in inner
    response = get_response(request)
               ^^^^^^^^^^^^^^^^^^^^^
  File "C:\Users\Ranjith\AppData\Local\Programs\Python\Python311\Lib\site-packages\django\core\handlers\base.py", line 197, in _get_response
    response = wrapped_callback(request, *callback_args, **callback_kwargs)
               ^^^^^^^^^^^^^^^^^^^^^^^^^^^^^^^^^^^^^^^^^^^^^^^^^^^^^^^^^^^^
  File "C:\Users\Ranjith\AppData\Local\Programs\Python\Python311\Lib\site-packages\django\contrib\auth\decorators.py", line 22, in _wrapper_view
    if test_func(request.user):
       ^^^^^^^^^^^^^^^^^^^^^^^
  File "C:\Users\Ranjith\AppData\Local\Programs\Python\Python311\Lib\site-packages\django\contrib\auth\decorators.py", line 51, in <lambda>
    lambda u: u.is_authenticated,
              ^^^^^^^^^^^^^^^^^^
  File "C:\Users\Ranjith\AppData\Local\Programs\Python\Python311\Lib\site-packages\django\utils\functional.py", line 266, in inner
    self._setup()
  File "C:\Users\Ranjith\AppData\Local\Programs\Python\Python311\Lib\site-packages\django\utils\functional.py", line 419, in _setup
    self._wrapped = self._setupfunc()
                    ^^^^^^^^^^^^^^^^^
  File "C:\Users\Ranjith\AppData\Local\Programs\Python\Python311\Lib\site-packages\django\contrib\auth\middleware.py", line 25, in <lambda>
    request.user = SimpleLazyObject(lambda: get_user(request))
                                            ^^^^^^^^^^^^^^^^^
  File "C:\Users\Ranjith\AppData\Local\Programs\Python\Python311\Lib\site-packages\django\contrib\auth\middleware.py", line 11, in get_user
    request._cached_user = auth.get_user(request)
                           ^^^^^^^^^^^^^^^^^^^^^^
  File "C:\Users\Ranjith\AppData\Local\Programs\Python\Python311\Lib\site-packages\django\contrib\auth\__init__.py", line 198, in get_user
    user = backend.get_user(user_id)
           ^^^^^^^^^^^^^^^^^^^^^^^^^
  File "C:\Users\Ranjith\AppData\Local\Programs\Python\Python311\Lib\site-packages\django\contrib\auth\backends.py", line 161, in get_user
    user = UserModel._default_manager.get(pk=user_id)
           ^^^^^^^^^^^^^^^^^^^^^^^^^^^^^^^^^^^^^^^^^^
  File "C:\Users\Ranjith\AppData\Local\Programs\Python\Python311\Lib\site-packages\django\db\models\manager.py", line 87, in manager_method
    return getattr(self.get_queryset(), name)(*args, **kwargs)
           ^^^^^^^^^^^^^^^^^^^^^^^^^^^^^^^^^^^^^^^^^^^^^^^^^^^
  File "C:\Users\Ranjith\AppData\Local\Programs\Python\Python311\Lib\site-packages\django\db\models\query.py", line 633, in get
    num = len(clone)
          ^^^^^^^^^^
  File "C:\Users\Ranjith\AppData\Local\Programs\Python\Python311\Lib\site-packages\django\db\models\query.py", line 380, in __len__
    self._fetch_all()
  File "C:\Users\Ranjith\AppData\Local\Programs\Python\Python311\Lib\site-packages\django\db\models\query.py", line 1881, in _fetch_all
    self._result_cache = list(self._iterable_class(self))
                         ^^^^^^^^^^^^^^^^^^^^^^^^^^^^^^^^
  File "C:\Users\Ranjith\AppData\Local\Programs\Python\Python311\Lib\site-packages\django\db\models\query.py", line 91, in __iter__
    results = compiler.execute_sql(
              ^^^^^^^^^^^^^^^^^^^^^
  File "C:\Users\Ranjith\AppData\Local\Programs\Python\Python311\Lib\site-packages\django\db\models\sql\compiler.py", line 1562, in execute_sql
    cursor.execute(sql, params)
  File "C:\Users\Ranjith\AppData\Local\Programs\Python\Python311\Lib\site-packages\django\db\backends\utils.py", line 102, in execute
    return super().execute(sql, params)
           ^^^^^^^^^^^^^^^^^^^^^^^^^^^^
  File "C:\Users\Ranjith\AppData\Local\Programs\Python\Python311\Lib\site-packages\django\db\backends\utils.py", line 67, in execute
    return self._execute_with_wrappers(
           ^^^^^^^^^^^^^^^^^^^^^^^^^^^^
  File "C:\Users\Ranjith\AppData\Local\Programs\Python\Python311\Lib\site-packages\django\db\backends\utils.py", line 80, in _execute_with_wrappers
    return executor(sql, params, many, context)
           ^^^^^^^^^^^^^^^^^^^^^^^^^^^^^^^^^^^^
  File "C:\Users\Ranjith\AppData\Local\Programs\Python\Python311\Lib\site-packages\django\db\backends\utils.py", line 84, in _execute
    with self.db.wrap_database_errors:
  File "C:\Users\Ranjith\AppData\Local\Programs\Python\Python311\Lib\site-packages\django\db\utils.py", line 91, in __exit__
    raise dj_exc_value.with_traceback(traceback) from exc_value
  File "C:\Users\Ranjith\AppData\Local\Programs\Python\Python311\Lib\site-packages\django\db\backends\utils.py", line 89, in _execute
    return self.cursor.execute(sql, params)
           ^^^^^^^^^^^^^^^^^^^^^^^^^^^^^^^^
  File "C:\Users\Ranjith\AppData\Local\Programs\Python\Python311\Lib\site-packages\django\db\backends\sqlite3\base.py", line 328, in execute
    return super().execute(query, params)
           ^^^^^^^^^^^^^^^^^^^^^^^^^^^^^^
django.db.utils.OperationalError: no such column: django_accounts_customuser.date_of_birth
"GET / HTTP/1.1" 500 170877
Not Found: /favicon.ico
"GET /favicon.ico HTTP/1.1" 404 3535
C:\Users\Ranjith\Desktop\Twitter\django_twitter\django_accounts\views.py changed, reloading.
Watching for file changes with StatReloader
"GET / HTTP/1.1" 200 2194
"GET / HTTP/1.1" 200 2194
"GET /static/images/welcomepage.jpg HTTP/1.1" 304 0
"POST /home/homepage/ HTTP/1.1" 200 3465
"GET /static/images/homepage.jpg HTTP/1.1" 304 0
"POST /profile/profile/ HTTP/1.1" 200 3018
Not Found: /media/images/default.jpeg
"GET /media/images/default.jpeg HTTP/1.1" 404 3629
"POST /profile/profile/ HTTP/1.1" 302 0
"GET /profile/profile/ HTTP/1.1" 200 3059
"GET /media/images/WhatsApp_Image_2023-11-07_at_12.30.52.jpeg HTTP/1.1" 200 12688
"POST /profile/profile/ HTTP/1.1" 302 0
"GET /profile/profile/ HTTP/1.1" 200 3065
"GET /media/images/WhatsApp_Image_2023-11-07_at_12.30.52.jpeg HTTP/1.1" 304 0
"POST /profile/profile/ HTTP/1.1" 302 0
"GET /profile/profile/ HTTP/1.1" 200 3065
"GET /media/images/WhatsApp_Image_2023-11-07_at_12.30.52.jpeg HTTP/1.1" 304 0
"GET /home/homepage/ HTTP/1.1" 200 3465
"POST /home/homepage/ HTTP/1.1" 200 3465
"GET /signout/ HTTP/1.1" 302 0
"GET /login/ HTTP/1.1" 200 2230
"GET /static/images/login_image.jpg HTTP/1.1" 304 0
"GET /signup/ HTTP/1.1" 200 2743
C:\Users\Ranjith\Desktop\Twitter\django_twitter\django_accounts\forms.py changed, reloading.
Watching for file changes with StatReloader
C:\Users\Ranjith\Desktop\Twitter\django_twitter\django_accounts\models.py changed, reloading.
Watching for file changes with StatReloader
- Broken pipe from ('127.0.0.1', 56147)
"GET /admin HTTP/1.1" 301 0
"GET /admin/ HTTP/1.1" 302 0
"GET /admin/login/?next=/admin/ HTTP/1.1" 200 4178
"GET /static/admin/css/dark_mode.css HTTP/1.1" 200 2929
"GET /static/admin/css/base.css HTTP/1.1" 200 21207
"GET /static/admin/css/nav_sidebar.css HTTP/1.1" 200 2694
"GET /static/admin/css/responsive.css HTTP/1.1" 200 18533
"GET /static/admin/css/login.css HTTP/1.1" 200 958
"GET /static/admin/js/nav_sidebar.js HTTP/1.1" 200 3063
"GET /static/admin/js/theme.js HTTP/1.1" 200 1943
Not Found: /favicon.ico
"GET /favicon.ico HTTP/1.1" 404 3364
"POST /admin/login/?next=/admin/ HTTP/1.1" 200 4360
"POST /admin/login/?next=/admin/ HTTP/1.1" 200 4360
Watching for file changes with StatReloader
"GET / HTTP/1.1" 302 0
"GET /login/?next=/ HTTP/1.1" 200 2230
"GET /static/images/login_image.jpg HTTP/1.1" 304 0
Not Found: /favicon.ico
"GET /favicon.ico HTTP/1.1" 404 3364
"POST /login/?next=/ HTTP/1.1" 302 0
"GET / HTTP/1.1" 200 2194
"GET /static/images/welcomepage.jpg HTTP/1.1" 304 0
"POST /home/homepage/ HTTP/1.1" 200 3465
"GET /static/images/homepage.jpg HTTP/1.1" 200 43
"GET /home/upload/ HTTP/1.1" 200 2617
"POST /home/homepage/ HTTP/1.1" 200 3465
"POST /home/homepage/ HTTP/1.1" 200 3465
"GET /static/images/homepage.jpg HTTP/1.1" 304 0
"POST /setting/settings/ HTTP/1.1" 200 4418
"GET /static/images/dashboard_image.jpg HTTP/1.1" 404 1938
"POST /setting/change_username/ HTTP/1.1" 200 2251
"GET /home/upload/ HTTP/1.1" 200 2617
"GET / HTTP/1.1" 200 2194
Watching for file changes with StatReloader
"GET / HTTP/1.1" 200 2194
"GET / HTTP/1.1" 302 0
"GET /login/?next=/ HTTP/1.1" 200 2230
"GET /static/images/login_image.jpg HTTP/1.1" 200 67388
Not Found: /favicon.ico
"GET /favicon.ico HTTP/1.1" 404 3364
"POST /login/?next=/ HTTP/1.1" 302 0
"GET / HTTP/1.1" 200 2194
"GET /static/images/welcomepage.jpg HTTP/1.1" 200 130059
"POST /home/homepage/ HTTP/1.1" 200 3465
"GET /static/images/homepage.jpg HTTP/1.1" 200 2589504
"POST /home/homepage/ HTTP/1.1" 200 3465
"POST /setting/settings/ HTTP/1.1" 200 4418
"GET /static/images/dashboard_image.jpg HTTP/1.1" 404 1938
"POST /home/homepage/ HTTP/1.1" 200 3465
"POST /profile/profile/ HTTP/1.1" 200 3113
"GET /media/images/WhatsApp_Image_2023-11-07_at_12.30.52.jpeg HTTP/1.1" 200 12688
Watching for file changes with StatReloader
"GET / HTTP/1.1" 200 2194
"GET / HTTP/1.1" 200 2194
"GET / HTTP/1.1" 200 2194
"GET /static/images/welcomepage.jpg HTTP/1.1" 304 0
"POST /home/homepage/ HTTP/1.1" 200 3464
"GET /static/images/homepage.jpg HTTP/1.1" 304 0
"POST /home/homepage/ HTTP/1.1" 200 3464
"POST /setting/settings/ HTTP/1.1" 200 4457
"POST /setting/settings/ HTTP/1.1" 200 4457
"GET /static/images/setting.jpg HTTP/1.1" 200 11908
"POST /home/homepage/ HTTP/1.1" 200 3464
"POST /profile/profile/ HTTP/1.1" 200 3255
"GET /static/images/profile.jpg HTTP/1.1" 200 22287
"GET /home/homepage/ HTTP/1.1" 200 3464
"POST /home/homepage/ HTTP/1.1" 200 3464
"POST /setting/settings/ HTTP/1.1" 200 4457
"POST /home/homepage/ HTTP/1.1" 200 3464
"POST /setting/settings/ HTTP/1.1" 200 4457
"POST /setting/change_username/ HTTP/1.1" 200 2251
"POST /setting/settings/ HTTP/1.1" 200 4457
"POST /setting/change_mobile-number/ HTTP/1.1" 200 2130
"POST /setting/settings/ HTTP/1.1" 200 4457
"POST /setting/change_email/ HTTP/1.1" 200 2085
"POST /setting/settings/ HTTP/1.1" 200 4457
"POST /setting/change_password/ HTTP/1.1" 200 2236
"POST /setting/settings/ HTTP/1.1" 200 4457
"POST /setting/change_username/ HTTP/1.1" 200 2251
Watching for file changes with StatReloader
"GET / HTTP/1.1" 200 2194
"GET /static/images/welcomepage.jpg HTTP/1.1" 304 0
"POST /home/homepage/ HTTP/1.1" 200 3464
"GET /static/images/homepage.jpg HTTP/1.1" 304 0
"POST /setting/settings/ HTTP/1.1" 200 4457
"GET /static/images/setting.jpg HTTP/1.1" 304 0
"POST /setting/change_mobile-number/ HTTP/1.1" 200 2158
Watching for file changes with StatReloader
"GET / HTTP/1.1" 200 2183
"GET /static/images/welcomepage.jpg HTTP/1.1" 304 0
Not Found: /favicon.ico
"GET /favicon.ico HTTP/1.1" 404 3364
"GET / HTTP/1.1" 200 2184
"POST /home/homepage/ HTTP/1.1" 200 3465
"GET /static/images/homepage.jpg HTTP/1.1" 304 0
"POST /home/homepage/ HTTP/1.1" 200 3465
"POST /setting/settings/ HTTP/1.1" 200 4457
"GET /static/images/setting.jpg HTTP/1.1" 304 0
"POST /setting/change_mobile-number/ HTTP/1.1" 200 2209
"POST /setting/settings/ HTTP/1.1" 200 4457
"POST /setting/change_email/ HTTP/1.1" 200 2114
"POST /setting/change_email/ HTTP/1.1" 200 2115
"GET / HTTP/1.1" 200 2184
Not Found: /favicon.ico
"GET /favicon.ico HTTP/1.1" 404 3364
"GET / HTTP/1.1" 200 2184
"GET / HTTP/1.1" 200 2184
"GET / HTTP/1.1" 200 2184
"GET / HTTP/1.1" 200 2184
"GET / HTTP/1.1" 200 2184
"POST /home/homepage/ HTTP/1.1" 200 3465
"GET /static/images/homepage.jpg HTTP/1.1" 200 2589504
"POST /setting/settings/ HTTP/1.1" 200 4457
"GET /static/images/setting.jpg HTTP/1.1" 200 11908
"POST /setting/change_email/ HTTP/1.1" 200 2115
Watching for file changes with StatReloader
"GET / HTTP/1.1" 200 2184
"GET /static/images/welcomepage.jpg HTTP/1.1" 200 130059
Not Found: /favicon.ico
"GET /favicon.ico HTTP/1.1" 404 3364
"POST /home/homepage/ HTTP/1.1" 200 3826
"GET /static/images/homepage.jpg HTTP/1.1" 304 0
"POST /setting/settings/ HTTP/1.1" 200 4457
"GET /static/images/setting.jpg HTTP/1.1" 304 0
"POST /setting/change_mobile-number/ HTTP/1.1" 200 2209
"POST /setting/change_mobile-number/ HTTP/1.1" 200 2209
"POST /setting/settings/ HTTP/1.1" 200 4457
"POST /setting/change_email/ HTTP/1.1" 200 2115
"POST /setting/settings/ HTTP/1.1" 200 4457
"POST /setting/change_password/ HTTP/1.1" 200 2266
"POST /setting/settings/ HTTP/1.1" 200 4457
"POST /setting/change_username/ HTTP/1.1" 200 2281
"POST /setting/settings/ HTTP/1.1" 200 4457
"POST /setting/change_email/ HTTP/1.1" 200 2115
"POST /setting/settings/ HTTP/1.1" 200 4457
C:\Users\Ranjith\Desktop\Twitter\django_twitter\django_setting\views.py changed, reloading.
Watching for file changes with StatReloader
C:\Users\Ranjith\Desktop\Twitter\django_twitter\django_setting\forms.py changed, reloading.
Watching for file changes with StatReloader
"POST /setting/change_password/ HTTP/1.1" 200 2266
"POST /setting/change_password/ HTTP/1.1" 200 2266
"POST /setting/change_password/ HTTP/1.1" 200 2266
"POST /setting/change_email/ HTTP/1.1" 200 2115
"POST /setting/change_email/ HTTP/1.1" 200 2115
"POST /setting/change_email/ HTTP/1.1" 200 2115
Watching for file changes with StatReloader
"GET / HTTP/1.1" 200 2184
"GET /static/images/welcomepage.jpg HTTP/1.1" 304 0
Not Found: /favicon.ico
"GET /favicon.ico HTTP/1.1" 404 3364
"GET /signout/ HTTP/1.1" 302 0
"GET /login/ HTTP/1.1" 200 2230
"GET /static/images/login_image.jpg HTTP/1.1" 304 0
Watching for file changes with StatReloader
"GET / HTTP/1.1" 302 0
"GET /login/?next=/ HTTP/1.1" 200 2230
"GET / HTTP/1.1" 302 0
"GET /login/?next=/ HTTP/1.1" 200 2230
Not Found: /favicon.ico
"GET /favicon.ico HTTP/1.1" 404 3364
"GET /signup/ HTTP/1.1" 200 2743
"GET /static/images/signup_image.jpg HTTP/1.1" 304 0
"POST /login/?next=/ HTTP/1.1" 302 0
"GET / HTTP/1.1" 200 2184
"POST /home/homepage/ HTTP/1.1" 200 3826
"GET /static/images/homepage.jpg HTTP/1.1" 304 0
"POST /setting/settings/ HTTP/1.1" 200 4457
"GET /static/images/setting.jpg HTTP/1.1" 304 0
"POST /home/homepage/ HTTP/1.1" 200 3826
"POST /profile/profile/ HTTP/1.1" 200 3255
"GET /media/images/WhatsApp_Image_2023-11-07_at_12.30.52.jpeg HTTP/1.1" 304 0
"GET /static/images/profile.jpg HTTP/1.1" 200 22287
"POST /profile/profile/ HTTP/1.1" 302 0
"GET /profile/profile/ HTTP/1.1" 200 3233
"GET /home/homepage/ HTTP/1.1" 200 3826
"POST /setting/settings/ HTTP/1.1" 200 4457
"POST /home/homepage/ HTTP/1.1" 200 3826
"POST /setting/settings/ HTTP/1.1" 200 4457
"POST /home/homepage/ HTTP/1.1" 200 3826
"POST /profile/profile/ HTTP/1.1" 200 3268
"POST /profile/profile/ HTTP/1.1" 200 3268
"POST /profile/profile/ HTTP/1.1" 200 3268
"POST /profile/profile/ HTTP/1.1" 200 3268
"POST /profile/profile/ HTTP/1.1" 200 3266
"POST /profile/profile/ HTTP/1.1" 200 3267
"POST /profile/profile/ HTTP/1.1" 200 3267
"POST /profile/profile/ HTTP/1.1" 200 3267
"POST /profile/profile/ HTTP/1.1" 200 3267
"POST /profile/profile/ HTTP/1.1" 200 3267
